[2024-11-06T06:17:15.129+0000] {taskinstance.py:1956} INFO - Dependencies all met for dep_context=non-requeueable deps ti=<TaskInstance: my_very_first_dag.my_very_first_task manual__2024-11-06T06:17:12.363532+00:00 [queued]>
[2024-11-06T06:17:15.145+0000] {taskinstance.py:1956} INFO - Dependencies all met for dep_context=requeueable deps ti=<TaskInstance: my_very_first_dag.my_very_first_task manual__2024-11-06T06:17:12.363532+00:00 [queued]>
[2024-11-06T06:17:15.146+0000] {taskinstance.py:2170} INFO - Starting attempt 1 of 1
[2024-11-06T06:17:15.180+0000] {taskinstance.py:2191} INFO - Executing <Task(PythonOperator): my_very_first_task> on 2024-11-06 06:17:12.363532+00:00
[2024-11-06T06:17:15.192+0000] {standard_task_runner.py:60} INFO - Started process 1305 to run task
[2024-11-06T06:17:15.198+0000] {standard_task_runner.py:87} INFO - Running: ['***', 'tasks', 'run', 'my_very_first_dag', 'my_very_first_task', 'manual__2024-11-06T06:17:12.363532+00:00', '--job-id', '8', '--raw', '--subdir', 'DAGS_FOLDER/my_first_dag.py', '--cfg-path', '/tmp/tmp_1i13tqh']
[2024-11-06T06:17:15.203+0000] {standard_task_runner.py:88} INFO - Job 8: Subtask my_very_first_task
[2024-11-06T06:17:15.241+0000] {warnings.py:109} WARNING - /home/***/.local/lib/python3.8/site-packages/***/settings.py:194: DeprecationWarning: The sql_alchemy_conn option in [core] has been moved to the sql_alchemy_conn option in [database] - the old setting has been used, but please update your config.
  SQL_ALCHEMY_CONN = conf.get("database", "SQL_ALCHEMY_CONN")

[2024-11-06T06:17:15.333+0000] {task_command.py:423} INFO - Running <TaskInstance: my_very_first_dag.my_very_first_task manual__2024-11-06T06:17:12.363532+00:00 [running]> on host 8b04ee1dc3cd
[2024-11-06T06:17:15.556+0000] {taskinstance.py:2480} INFO - Exporting env vars: AIRFLOW_CTX_DAG_OWNER='***' AIRFLOW_CTX_DAG_ID='my_very_first_dag' AIRFLOW_CTX_TASK_ID='my_very_first_task' AIRFLOW_CTX_EXECUTION_DATE='2024-11-06T06:17:12.363532+00:00' AIRFLOW_CTX_TRY_NUMBER='1' AIRFLOW_CTX_DAG_RUN_ID='manual__2024-11-06T06:17:12.363532+00:00'
[2024-11-06T06:17:15.558+0000] {taskinstance.py:2698} ERROR - Task failed with exception
Traceback (most recent call last):
  File "/home/airflow/.local/lib/python3.8/site-packages/airflow/models/taskinstance.py", line 433, in _execute_task
    result = execute_callable(context=context, **execute_callable_kwargs)
  File "/home/airflow/.local/lib/python3.8/site-packages/airflow/operators/python.py", line 199, in execute
    return_value = self.execute_callable()
  File "/home/airflow/.local/lib/python3.8/site-packages/airflow/operators/python.py", line 216, in execute_callable
    return self.python_callable(*self.op_args, **self.op_kwargs)
  File "/opt/airflow/dags/my_first_dag.py", line 20, in print_date_and_hello
    raise TypeError('This will not work')
TypeError: This will not work
[2024-11-06T06:17:15.575+0000] {taskinstance.py:1138} INFO - Marking task as FAILED. dag_id=my_very_first_dag, task_id=my_very_first_task, execution_date=20241106T061712, start_date=20241106T061715, end_date=20241106T061715
[2024-11-06T06:17:15.598+0000] {standard_task_runner.py:107} ERROR - Failed to execute job 8 for task my_very_first_task (This will not work; 1305)
[2024-11-06T06:17:15.629+0000] {local_task_job_runner.py:234} INFO - Task exited with return code 1
[2024-11-06T06:17:15.676+0000] {taskinstance.py:3280} INFO - 0 downstream tasks scheduled from follow-on schedule check
