[2024-11-07T09:05:58.821+0000] {taskinstance.py:1956} INFO - Dependencies all met for dep_context=non-requeueable deps ti=<TaskInstance: openweatherdata_dag.task_5 manual__2024-11-07T09:05:38.981136+00:00 [queued]>
[2024-11-07T09:05:58.839+0000] {taskinstance.py:1956} INFO - Dependencies all met for dep_context=requeueable deps ti=<TaskInstance: openweatherdata_dag.task_5 manual__2024-11-07T09:05:38.981136+00:00 [queued]>
[2024-11-07T09:05:58.839+0000] {taskinstance.py:2170} INFO - Starting attempt 1 of 1
[2024-11-07T09:05:58.860+0000] {taskinstance.py:2191} INFO - Executing <Task(PythonOperator): task_5> on 2024-11-07 09:05:38.981136+00:00
[2024-11-07T09:05:58.874+0000] {standard_task_runner.py:60} INFO - Started process 675 to run task
[2024-11-07T09:05:58.880+0000] {standard_task_runner.py:87} INFO - Running: ['***', 'tasks', 'run', 'openweatherdata_dag', 'task_5', 'manual__2024-11-07T09:05:38.981136+00:00', '--job-id', '166', '--raw', '--subdir', 'DAGS_FOLDER/model_meteo.py', '--cfg-path', '/tmp/tmp3wut9ngl']
[2024-11-07T09:05:58.881+0000] {standard_task_runner.py:88} INFO - Job 166: Subtask task_5
[2024-11-07T09:05:58.902+0000] {warnings.py:109} WARNING - /home/***/.local/lib/python3.8/site-packages/***/settings.py:194: DeprecationWarning: The sql_alchemy_conn option in [core] has been moved to the sql_alchemy_conn option in [database] - the old setting has been used, but please update your config.
  SQL_ALCHEMY_CONN = conf.get("database", "SQL_ALCHEMY_CONN")

[2024-11-07T09:05:58.955+0000] {task_command.py:423} INFO - Running <TaskInstance: openweatherdata_dag.task_5 manual__2024-11-07T09:05:38.981136+00:00 [running]> on host 8a2ba9ce15fe
[2024-11-07T09:05:59.128+0000] {taskinstance.py:2480} INFO - Exporting env vars: AIRFLOW_CTX_DAG_OWNER='***' AIRFLOW_CTX_DAG_ID='openweatherdata_dag' AIRFLOW_CTX_TASK_ID='task_5' AIRFLOW_CTX_EXECUTION_DATE='2024-11-07T09:05:38.981136+00:00' AIRFLOW_CTX_TRY_NUMBER='1' AIRFLOW_CTX_DAG_RUN_ID='manual__2024-11-07T09:05:38.981136+00:00'
[2024-11-07T09:05:59.212+0000] {logging_mixin.py:188} INFO - LinearRegression() saved at  clean_data/best_model.pickle
[2024-11-07T09:05:59.213+0000] {taskinstance.py:2698} ERROR - Task failed with exception
Traceback (most recent call last):
  File "/home/airflow/.local/lib/python3.8/site-packages/airflow/models/taskinstance.py", line 433, in _execute_task
    result = execute_callable(context=context, **execute_callable_kwargs)
  File "/home/airflow/.local/lib/python3.8/site-packages/airflow/operators/python.py", line 199, in execute
    return_value = self.execute_callable()
  File "/home/airflow/.local/lib/python3.8/site-packages/airflow/operators/python.py", line 216, in execute_callable
    return self.python_callable(*self.op_args, **self.op_kwargs)
  File "/opt/airflow/dags/model_meteo.py", line 209, in train_best_model
    train_and_save_model(
  File "/opt/airflow/dags/model_meteo.py", line 148, in train_and_save_model
    dump(model, path_to_model)
  File "/home/airflow/.local/lib/python3.8/site-packages/joblib/numpy_pickle.py", line 552, in dump
    with open(filename, 'wb') as f:
FileNotFoundError: [Errno 2] No such file or directory: 'clean_data/best_model.pickle'
[2024-11-07T09:05:59.227+0000] {taskinstance.py:1138} INFO - Marking task as FAILED. dag_id=openweatherdata_dag, task_id=task_5, execution_date=20241107T090538, start_date=20241107T090558, end_date=20241107T090559
[2024-11-07T09:05:59.247+0000] {standard_task_runner.py:107} ERROR - Failed to execute job 166 for task task_5 ([Errno 2] No such file or directory: 'clean_data/best_model.pickle'; 675)
[2024-11-07T09:05:59.295+0000] {local_task_job_runner.py:234} INFO - Task exited with return code 1
[2024-11-07T09:05:59.325+0000] {taskinstance.py:3280} INFO - 0 downstream tasks scheduled from follow-on schedule check
