[2024-11-07T07:49:54.704+0000] {taskinstance.py:1956} INFO - Dependencies all met for dep_context=non-requeueable deps ti=<TaskInstance: openweatherdata_dag.task_2 manual__2024-11-07T07:49:45.833371+00:00 [queued]>
[2024-11-07T07:49:54.720+0000] {taskinstance.py:1956} INFO - Dependencies all met for dep_context=requeueable deps ti=<TaskInstance: openweatherdata_dag.task_2 manual__2024-11-07T07:49:45.833371+00:00 [queued]>
[2024-11-07T07:49:54.720+0000] {taskinstance.py:2170} INFO - Starting attempt 1 of 1
[2024-11-07T07:49:54.742+0000] {taskinstance.py:2191} INFO - Executing <Task(PythonOperator): task_2> on 2024-11-07 07:49:45.833371+00:00
[2024-11-07T07:49:54.756+0000] {standard_task_runner.py:60} INFO - Started process 6474 to run task
[2024-11-07T07:49:54.762+0000] {standard_task_runner.py:87} INFO - Running: ['***', 'tasks', 'run', 'openweatherdata_dag', 'task_2', 'manual__2024-11-07T07:49:45.833371+00:00', '--job-id', '88', '--raw', '--subdir', 'DAGS_FOLDER/model_meteo.py', '--cfg-path', '/tmp/tmpecca3uu1']
[2024-11-07T07:49:54.765+0000] {standard_task_runner.py:88} INFO - Job 88: Subtask task_2
[2024-11-07T07:49:54.790+0000] {warnings.py:109} WARNING - /home/***/.local/lib/python3.8/site-packages/***/settings.py:194: DeprecationWarning: The sql_alchemy_conn option in [core] has been moved to the sql_alchemy_conn option in [database] - the old setting has been used, but please update your config.
  SQL_ALCHEMY_CONN = conf.get("database", "SQL_ALCHEMY_CONN")

[2024-11-07T07:49:54.870+0000] {task_command.py:423} INFO - Running <TaskInstance: openweatherdata_dag.task_2 manual__2024-11-07T07:49:45.833371+00:00 [running]> on host 8a2ba9ce15fe
[2024-11-07T07:49:55.008+0000] {taskinstance.py:2480} INFO - Exporting env vars: AIRFLOW_CTX_DAG_OWNER='***' AIRFLOW_CTX_DAG_ID='openweatherdata_dag' AIRFLOW_CTX_TASK_ID='task_2' AIRFLOW_CTX_EXECUTION_DATE='2024-11-07T07:49:45.833371+00:00' AIRFLOW_CTX_TRY_NUMBER='1' AIRFLOW_CTX_DAG_RUN_ID='manual__2024-11-07T07:49:45.833371+00:00'
[2024-11-07T07:49:55.010+0000] {taskinstance.py:2698} ERROR - Task failed with exception
Traceback (most recent call last):
  File "/home/airflow/.local/lib/python3.8/site-packages/airflow/models/taskinstance.py", line 433, in _execute_task
    result = execute_callable(context=context, **execute_callable_kwargs)
  File "/home/airflow/.local/lib/python3.8/site-packages/airflow/operators/python.py", line 199, in execute
    return_value = self.execute_callable()
  File "/home/airflow/.local/lib/python3.8/site-packages/airflow/operators/python.py", line 216, in execute_callable
    return self.python_callable(*self.op_args, **self.op_kwargs)
  File "/opt/airflow/dags/model_meteo.py", line 65, in transform_data_into_csv
    data_city = json.loads(data_temp[data_city])
TypeError: list indices must be integers or slices, not dict
[2024-11-07T07:49:55.027+0000] {taskinstance.py:1138} INFO - Marking task as FAILED. dag_id=openweatherdata_dag, task_id=task_2, execution_date=20241107T074945, start_date=20241107T074954, end_date=20241107T074955
[2024-11-07T07:49:55.047+0000] {standard_task_runner.py:107} ERROR - Failed to execute job 88 for task task_2 (list indices must be integers or slices, not dict; 6474)
[2024-11-07T07:49:55.100+0000] {local_task_job_runner.py:234} INFO - Task exited with return code 1
[2024-11-07T07:49:55.160+0000] {taskinstance.py:3280} INFO - 0 downstream tasks scheduled from follow-on schedule check
