[2024-11-07T08:58:59.606+0000] {taskinstance.py:1956} INFO - Dependencies all met for dep_context=non-requeueable deps ti=<TaskInstance: openweatherdata_dag.group_4.task_4c manual__2024-11-07T08:58:46.800776+00:00 [queued]>
[2024-11-07T08:58:59.627+0000] {taskinstance.py:1956} INFO - Dependencies all met for dep_context=requeueable deps ti=<TaskInstance: openweatherdata_dag.group_4.task_4c manual__2024-11-07T08:58:46.800776+00:00 [queued]>
[2024-11-07T08:58:59.628+0000] {taskinstance.py:2170} INFO - Starting attempt 1 of 1
[2024-11-07T08:58:59.654+0000] {taskinstance.py:2191} INFO - Executing <Task(PythonOperator): group_4.task_4c> on 2024-11-07 08:58:46.800776+00:00
[2024-11-07T08:58:59.670+0000] {standard_task_runner.py:60} INFO - Started process 302 to run task
[2024-11-07T08:58:59.679+0000] {standard_task_runner.py:87} INFO - Running: ['***', 'tasks', 'run', 'openweatherdata_dag', 'group_4.task_4c', 'manual__2024-11-07T08:58:46.800776+00:00', '--job-id', '140', '--raw', '--subdir', 'DAGS_FOLDER/model_meteo.py', '--cfg-path', '/tmp/tmp3h6vy_o5']
[2024-11-07T08:58:59.681+0000] {standard_task_runner.py:88} INFO - Job 140: Subtask group_4.task_4c
[2024-11-07T08:58:59.709+0000] {warnings.py:109} WARNING - /home/***/.local/lib/python3.8/site-packages/***/settings.py:194: DeprecationWarning: The sql_alchemy_conn option in [core] has been moved to the sql_alchemy_conn option in [database] - the old setting has been used, but please update your config.
  SQL_ALCHEMY_CONN = conf.get("database", "SQL_ALCHEMY_CONN")

[2024-11-07T08:58:59.781+0000] {task_command.py:423} INFO - Running <TaskInstance: openweatherdata_dag.group_4.task_4c manual__2024-11-07T08:58:46.800776+00:00 [running]> on host 8a2ba9ce15fe
[2024-11-07T08:58:59.958+0000] {taskinstance.py:2480} INFO - Exporting env vars: AIRFLOW_CTX_DAG_OWNER='***' AIRFLOW_CTX_DAG_ID='openweatherdata_dag' AIRFLOW_CTX_TASK_ID='group_4.task_4c' AIRFLOW_CTX_EXECUTION_DATE='2024-11-07T08:58:46.800776+00:00' AIRFLOW_CTX_TRY_NUMBER='1' AIRFLOW_CTX_DAG_RUN_ID='manual__2024-11-07T08:58:46.800776+00:00'
[2024-11-07T08:59:00.031+0000] {taskinstance.py:2698} ERROR - Task failed with exception
Traceback (most recent call last):
  File "/home/airflow/.local/lib/python3.8/site-packages/airflow/models/taskinstance.py", line 433, in _execute_task
    result = execute_callable(context=context, **execute_callable_kwargs)
  File "/home/airflow/.local/lib/python3.8/site-packages/airflow/operators/python.py", line 199, in execute
    return_value = self.execute_callable()
  File "/home/airflow/.local/lib/python3.8/site-packages/airflow/operators/python.py", line 216, in execute_callable
    return self.python_callable(*self.op_args, **self.op_kwargs)
  File "/opt/airflow/dags/model_meteo.py", line 123, in train_and_score_model
    score = compute_model_score(model, X, y)
  File "/opt/airflow/dags/model_meteo.py", line 144, in compute_model_score
    cross_validation = cross_val_score(
  File "/home/airflow/.local/lib/python3.8/site-packages/sklearn/model_selection/_validation.py", line 562, in cross_val_score
    cv_results = cross_validate(
  File "/home/airflow/.local/lib/python3.8/site-packages/sklearn/utils/_param_validation.py", line 214, in wrapper
    return func(*args, **kwargs)
  File "/home/airflow/.local/lib/python3.8/site-packages/sklearn/model_selection/_validation.py", line 309, in cross_validate
    results = parallel(
  File "/home/airflow/.local/lib/python3.8/site-packages/sklearn/utils/parallel.py", line 65, in __call__
    return super().__call__(iterable_with_config)
  File "/home/airflow/.local/lib/python3.8/site-packages/joblib/parallel.py", line 1918, in __call__
    return output if self.return_generator else list(output)
  File "/home/airflow/.local/lib/python3.8/site-packages/joblib/parallel.py", line 1844, in _get_sequential_output
    for func, args, kwargs in iterable:
  File "/home/airflow/.local/lib/python3.8/site-packages/sklearn/utils/parallel.py", line 61, in <genexpr>
    iterable_with_config = (
  File "/home/airflow/.local/lib/python3.8/site-packages/sklearn/model_selection/_validation.py", line 309, in <genexpr>
    results = parallel(
  File "/home/airflow/.local/lib/python3.8/site-packages/sklearn/model_selection/_split.py", line 370, in split
    raise ValueError(
ValueError: Cannot have number of splits n_splits=3 greater than the number of samples: n_samples=0.
[2024-11-07T08:59:00.048+0000] {taskinstance.py:1138} INFO - Marking task as FAILED. dag_id=openweatherdata_dag, task_id=group_4.task_4c, execution_date=20241107T085846, start_date=20241107T085859, end_date=20241107T085900
[2024-11-07T08:59:00.067+0000] {standard_task_runner.py:107} ERROR - Failed to execute job 140 for task group_4.task_4c (Cannot have number of splits n_splits=3 greater than the number of samples: n_samples=0.; 302)
[2024-11-07T08:59:00.100+0000] {local_task_job_runner.py:234} INFO - Task exited with return code 1
[2024-11-07T08:59:00.167+0000] {taskinstance.py:3280} INFO - 0 downstream tasks scheduled from follow-on schedule check
