[2024-11-07T09:00:59.204+0000] {taskinstance.py:1956} INFO - Dependencies all met for dep_context=non-requeueable deps ti=<TaskInstance: openweatherdata_dag.group_4.task_4a manual__2024-11-07T09:00:44.792388+00:00 [queued]>
[2024-11-07T09:00:59.222+0000] {taskinstance.py:1956} INFO - Dependencies all met for dep_context=requeueable deps ti=<TaskInstance: openweatherdata_dag.group_4.task_4a manual__2024-11-07T09:00:44.792388+00:00 [queued]>
[2024-11-07T09:00:59.223+0000] {taskinstance.py:2170} INFO - Starting attempt 1 of 1
[2024-11-07T09:00:59.253+0000] {taskinstance.py:2191} INFO - Executing <Task(PythonOperator): group_4.task_4a> on 2024-11-07 09:00:44.792388+00:00
[2024-11-07T09:00:59.266+0000] {standard_task_runner.py:60} INFO - Started process 403 to run task
[2024-11-07T09:00:59.272+0000] {standard_task_runner.py:87} INFO - Running: ['***', 'tasks', 'run', 'openweatherdata_dag', 'group_4.task_4a', 'manual__2024-11-07T09:00:44.792388+00:00', '--job-id', '146', '--raw', '--subdir', 'DAGS_FOLDER/model_meteo.py', '--cfg-path', '/tmp/tmpn3j6vl8p']
[2024-11-07T09:00:59.276+0000] {standard_task_runner.py:88} INFO - Job 146: Subtask group_4.task_4a
[2024-11-07T09:00:59.295+0000] {warnings.py:109} WARNING - /home/***/.local/lib/python3.8/site-packages/***/settings.py:194: DeprecationWarning: The sql_alchemy_conn option in [core] has been moved to the sql_alchemy_conn option in [database] - the old setting has been used, but please update your config.
  SQL_ALCHEMY_CONN = conf.get("database", "SQL_ALCHEMY_CONN")

[2024-11-07T09:00:59.354+0000] {task_command.py:423} INFO - Running <TaskInstance: openweatherdata_dag.group_4.task_4a manual__2024-11-07T09:00:44.792388+00:00 [running]> on host 8a2ba9ce15fe
[2024-11-07T09:00:59.519+0000] {taskinstance.py:2480} INFO - Exporting env vars: AIRFLOW_CTX_DAG_OWNER='***' AIRFLOW_CTX_DAG_ID='openweatherdata_dag' AIRFLOW_CTX_TASK_ID='group_4.task_4a' AIRFLOW_CTX_EXECUTION_DATE='2024-11-07T09:00:44.792388+00:00' AIRFLOW_CTX_TRY_NUMBER='1' AIRFLOW_CTX_DAG_RUN_ID='manual__2024-11-07T09:00:44.792388+00:00'
[2024-11-07T09:00:59.531+0000] {taskinstance.py:2698} ERROR - Task failed with exception
Traceback (most recent call last):
  File "/home/airflow/.local/lib/python3.8/site-packages/airflow/models/taskinstance.py", line 433, in _execute_task
    result = execute_callable(context=context, **execute_callable_kwargs)
  File "/home/airflow/.local/lib/python3.8/site-packages/airflow/operators/python.py", line 199, in execute
    return_value = self.execute_callable()
  File "/home/airflow/.local/lib/python3.8/site-packages/airflow/operators/python.py", line 216, in execute_callable
    return self.python_callable(*self.op_args, **self.op_kwargs)
  File "/opt/airflow/dags/model_meteo.py", line 104, in train_and_score_model
    X, y = prepare_data('/app/clean_data/fulldata.csv')
  File "/opt/airflow/dags/model_meteo.py", line 153, in prepare_data
    assert len(df) > 100000000000, (len(df), path_to_data)
AssertionError: (18, '/app/clean_data/fulldata.csv')
[2024-11-07T09:00:59.550+0000] {taskinstance.py:1138} INFO - Marking task as FAILED. dag_id=openweatherdata_dag, task_id=group_4.task_4a, execution_date=20241107T090044, start_date=20241107T090059, end_date=20241107T090059
[2024-11-07T09:00:59.576+0000] {standard_task_runner.py:107} ERROR - Failed to execute job 146 for task group_4.task_4a ((18, '/app/clean_data/fulldata.csv'); 403)
[2024-11-07T09:00:59.614+0000] {local_task_job_runner.py:234} INFO - Task exited with return code 1
[2024-11-07T09:00:59.650+0000] {taskinstance.py:3280} INFO - 0 downstream tasks scheduled from follow-on schedule check
