[2024-11-07T07:50:51.179+0000] {taskinstance.py:1956} INFO - Dependencies all met for dep_context=non-requeueable deps ti=<TaskInstance: openweatherdata_dag.task_3 manual__2024-11-07T07:50:42.012698+00:00 [queued]>
[2024-11-07T07:50:51.223+0000] {taskinstance.py:1956} INFO - Dependencies all met for dep_context=requeueable deps ti=<TaskInstance: openweatherdata_dag.task_3 manual__2024-11-07T07:50:42.012698+00:00 [queued]>
[2024-11-07T07:50:51.223+0000] {taskinstance.py:2170} INFO - Starting attempt 1 of 1
[2024-11-07T07:50:51.257+0000] {taskinstance.py:2191} INFO - Executing <Task(PythonOperator): task_3> on 2024-11-07 07:50:42.012698+00:00
[2024-11-07T07:50:51.294+0000] {standard_task_runner.py:60} INFO - Started process 6525 to run task
[2024-11-07T07:50:51.314+0000] {standard_task_runner.py:87} INFO - Running: ['***', 'tasks', 'run', 'openweatherdata_dag', 'task_3', 'manual__2024-11-07T07:50:42.012698+00:00', '--job-id', '91', '--raw', '--subdir', 'DAGS_FOLDER/model_meteo.py', '--cfg-path', '/tmp/tmpzzychym6']
[2024-11-07T07:50:51.317+0000] {standard_task_runner.py:88} INFO - Job 91: Subtask task_3
[2024-11-07T07:50:51.346+0000] {warnings.py:109} WARNING - /home/***/.local/lib/python3.8/site-packages/***/settings.py:194: DeprecationWarning: The sql_alchemy_conn option in [core] has been moved to the sql_alchemy_conn option in [database] - the old setting has been used, but please update your config.
  SQL_ALCHEMY_CONN = conf.get("database", "SQL_ALCHEMY_CONN")

[2024-11-07T07:50:51.427+0000] {task_command.py:423} INFO - Running <TaskInstance: openweatherdata_dag.task_3 manual__2024-11-07T07:50:42.012698+00:00 [running]> on host 8a2ba9ce15fe
[2024-11-07T07:50:51.575+0000] {taskinstance.py:2480} INFO - Exporting env vars: AIRFLOW_CTX_DAG_OWNER='***' AIRFLOW_CTX_DAG_ID='openweatherdata_dag' AIRFLOW_CTX_TASK_ID='task_3' AIRFLOW_CTX_EXECUTION_DATE='2024-11-07T07:50:42.012698+00:00' AIRFLOW_CTX_TRY_NUMBER='1' AIRFLOW_CTX_DAG_RUN_ID='manual__2024-11-07T07:50:42.012698+00:00'
[2024-11-07T07:50:51.583+0000] {taskinstance.py:2698} ERROR - Task failed with exception
Traceback (most recent call last):
  File "/home/airflow/.local/lib/python3.8/site-packages/airflow/models/taskinstance.py", line 433, in _execute_task
    result = execute_callable(context=context, **execute_callable_kwargs)
  File "/home/airflow/.local/lib/python3.8/site-packages/airflow/operators/python.py", line 199, in execute
    return_value = self.execute_callable()
  File "/home/airflow/.local/lib/python3.8/site-packages/airflow/operators/python.py", line 216, in execute_callable
    return self.python_callable(*self.op_args, **self.op_kwargs)
  File "/opt/airflow/dags/model_meteo.py", line 65, in transform_data_into_csv
    data_city = json.loads(data_city)
  File "/usr/local/lib/python3.8/json/__init__.py", line 341, in loads
    raise TypeError(f'the JSON object must be str, bytes or bytearray, '
TypeError: the JSON object must be str, bytes or bytearray, not dict
[2024-11-07T07:50:51.599+0000] {taskinstance.py:1138} INFO - Marking task as FAILED. dag_id=openweatherdata_dag, task_id=task_3, execution_date=20241107T075042, start_date=20241107T075051, end_date=20241107T075051
[2024-11-07T07:50:51.620+0000] {standard_task_runner.py:107} ERROR - Failed to execute job 91 for task task_3 (the JSON object must be str, bytes or bytearray, not dict; 6525)
[2024-11-07T07:50:51.673+0000] {local_task_job_runner.py:234} INFO - Task exited with return code 1
[2024-11-07T07:50:51.753+0000] {taskinstance.py:3280} INFO - 0 downstream tasks scheduled from follow-on schedule check
