[2024-11-07T07:38:10.422+0000] {taskinstance.py:1956} INFO - Dependencies all met for dep_context=non-requeueable deps ti=<TaskInstance: openweatherdata_dag.task_3 manual__2024-11-07T07:38:01.156315+00:00 [queued]>
[2024-11-07T07:38:10.437+0000] {taskinstance.py:1956} INFO - Dependencies all met for dep_context=requeueable deps ti=<TaskInstance: openweatherdata_dag.task_3 manual__2024-11-07T07:38:01.156315+00:00 [queued]>
[2024-11-07T07:38:10.438+0000] {taskinstance.py:2170} INFO - Starting attempt 1 of 1
[2024-11-07T07:38:10.459+0000] {taskinstance.py:2191} INFO - Executing <Task(PythonOperator): task_3> on 2024-11-07 07:38:01.156315+00:00
[2024-11-07T07:38:10.474+0000] {standard_task_runner.py:60} INFO - Started process 6004 to run task
[2024-11-07T07:38:10.479+0000] {standard_task_runner.py:87} INFO - Running: ['***', 'tasks', 'run', 'openweatherdata_dag', 'task_3', 'manual__2024-11-07T07:38:01.156315+00:00', '--job-id', '77', '--raw', '--subdir', 'DAGS_FOLDER/model_meteo.py', '--cfg-path', '/tmp/tmpwj9amhdh']
[2024-11-07T07:38:10.481+0000] {standard_task_runner.py:88} INFO - Job 77: Subtask task_3
[2024-11-07T07:38:10.503+0000] {warnings.py:109} WARNING - /home/***/.local/lib/python3.8/site-packages/***/settings.py:194: DeprecationWarning: The sql_alchemy_conn option in [core] has been moved to the sql_alchemy_conn option in [database] - the old setting has been used, but please update your config.
  SQL_ALCHEMY_CONN = conf.get("database", "SQL_ALCHEMY_CONN")

[2024-11-07T07:38:10.564+0000] {task_command.py:423} INFO - Running <TaskInstance: openweatherdata_dag.task_3 manual__2024-11-07T07:38:01.156315+00:00 [running]> on host 8a2ba9ce15fe
[2024-11-07T07:38:10.707+0000] {taskinstance.py:2480} INFO - Exporting env vars: AIRFLOW_CTX_DAG_OWNER='***' AIRFLOW_CTX_DAG_ID='openweatherdata_dag' AIRFLOW_CTX_TASK_ID='task_3' AIRFLOW_CTX_EXECUTION_DATE='2024-11-07T07:38:01.156315+00:00' AIRFLOW_CTX_TRY_NUMBER='1' AIRFLOW_CTX_DAG_RUN_ID='manual__2024-11-07T07:38:01.156315+00:00'
[2024-11-07T07:38:10.710+0000] {taskinstance.py:2698} ERROR - Task failed with exception
Traceback (most recent call last):
  File "/home/airflow/.local/lib/python3.8/site-packages/airflow/models/taskinstance.py", line 433, in _execute_task
    result = execute_callable(context=context, **execute_callable_kwargs)
  File "/home/airflow/.local/lib/python3.8/site-packages/airflow/operators/python.py", line 199, in execute
    return_value = self.execute_callable()
  File "/home/airflow/.local/lib/python3.8/site-packages/airflow/operators/python.py", line 216, in execute_callable
    return self.python_callable(*self.op_args, **self.op_kwargs)
  File "/opt/airflow/dags/model_meteo.py", line 60, in transform_data_into_csv
    data_temp = json.load(file)
  File "/usr/local/lib/python3.8/json/__init__.py", line 293, in load
    return loads(fp.read(),
  File "/usr/local/lib/python3.8/json/__init__.py", line 357, in loads
    return _default_decoder.decode(s)
  File "/usr/local/lib/python3.8/json/decoder.py", line 340, in decode
    raise JSONDecodeError("Extra data", s, end)
json.decoder.JSONDecodeError: Extra data: line 1 column 575 (char 574)
[2024-11-07T07:38:10.723+0000] {taskinstance.py:1138} INFO - Marking task as FAILED. dag_id=openweatherdata_dag, task_id=task_3, execution_date=20241107T073801, start_date=20241107T073810, end_date=20241107T073810
[2024-11-07T07:38:10.748+0000] {standard_task_runner.py:107} ERROR - Failed to execute job 77 for task task_3 (Extra data: line 1 column 575 (char 574); 6004)
[2024-11-07T07:38:10.815+0000] {local_task_job_runner.py:234} INFO - Task exited with return code 1
[2024-11-07T07:38:10.857+0000] {taskinstance.py:3280} INFO - 0 downstream tasks scheduled from follow-on schedule check
