[2024-11-06T07:59:38.479+0000] {taskinstance.py:1956} INFO - Dependencies all met for dep_context=non-requeueable deps ti=<TaskInstance: sensor_dag.check_file manual__2024-11-06T07:59:35.685750+00:00 [queued]>
[2024-11-06T07:59:38.502+0000] {taskinstance.py:1956} INFO - Dependencies all met for dep_context=requeueable deps ti=<TaskInstance: sensor_dag.check_file manual__2024-11-06T07:59:35.685750+00:00 [queued]>
[2024-11-06T07:59:38.503+0000] {taskinstance.py:2170} INFO - Starting attempt 1 of 1
[2024-11-06T07:59:38.561+0000] {taskinstance.py:2191} INFO - Executing <Task(FileSensor): check_file> on 2024-11-06 07:59:35.685750+00:00
[2024-11-06T07:59:38.572+0000] {standard_task_runner.py:60} INFO - Started process 4817 to run task
[2024-11-06T07:59:38.577+0000] {standard_task_runner.py:87} INFO - Running: ['***', 'tasks', 'run', 'sensor_dag', 'check_file', 'manual__2024-11-06T07:59:35.685750+00:00', '--job-id', '58', '--raw', '--subdir', 'DAGS_FOLDER/dag_filesensor.py', '--cfg-path', '/tmp/tmpbrm3nux9']
[2024-11-06T07:59:38.581+0000] {standard_task_runner.py:88} INFO - Job 58: Subtask check_file
[2024-11-06T07:59:38.624+0000] {warnings.py:109} WARNING - /home/***/.local/lib/python3.8/site-packages/***/settings.py:194: DeprecationWarning: The sql_alchemy_conn option in [core] has been moved to the sql_alchemy_conn option in [database] - the old setting has been used, but please update your config.
  SQL_ALCHEMY_CONN = conf.get("database", "SQL_ALCHEMY_CONN")

[2024-11-06T07:59:38.715+0000] {task_command.py:423} INFO - Running <TaskInstance: sensor_dag.check_file manual__2024-11-06T07:59:35.685750+00:00 [running]> on host 8b04ee1dc3cd
[2024-11-06T07:59:38.885+0000] {taskinstance.py:2480} INFO - Exporting env vars: AIRFLOW_CTX_DAG_OWNER='***' AIRFLOW_CTX_DAG_ID='sensor_dag' AIRFLOW_CTX_TASK_ID='check_file' AIRFLOW_CTX_EXECUTION_DATE='2024-11-06T07:59:35.685750+00:00' AIRFLOW_CTX_TRY_NUMBER='1' AIRFLOW_CTX_DAG_RUN_ID='manual__2024-11-06T07:59:35.685750+00:00'
[2024-11-06T07:59:38.939+0000] {taskinstance.py:2698} ERROR - Task failed with exception
Traceback (most recent call last):
  File "/home/airflow/.local/lib/python3.8/site-packages/airflow/models/taskinstance.py", line 433, in _execute_task
    result = execute_callable(context=context, **execute_callable_kwargs)
  File "/home/airflow/.local/lib/python3.8/site-packages/airflow/sensors/base.py", line 265, in execute
    raise e
  File "/home/airflow/.local/lib/python3.8/site-packages/airflow/sensors/base.py", line 247, in execute
    poke_return = self.poke(context)
  File "/home/airflow/.local/lib/python3.8/site-packages/airflow/sensors/filesystem.py", line 63, in poke
    hook = FSHook(self.fs_conn_id)
  File "/home/airflow/.local/lib/python3.8/site-packages/airflow/hooks/filesystem.py", line 64, in __init__
    conn = self.get_connection(fs_conn_id)
  File "/home/airflow/.local/lib/python3.8/site-packages/airflow/hooks/base.py", line 82, in get_connection
    conn = Connection.get_connection_from_secrets(conn_id)
  File "/home/airflow/.local/lib/python3.8/site-packages/airflow/models/connection.py", line 479, in get_connection_from_secrets
    raise AirflowNotFoundException(f"The conn_id `{conn_id}` isn't defined")
airflow.exceptions.AirflowNotFoundException: The conn_id `my_filesystem_connection` isn't defined
[2024-11-06T07:59:38.945+0000] {taskinstance.py:1138} INFO - Marking task as FAILED. dag_id=sensor_dag, task_id=check_file, execution_date=20241106T075935, start_date=20241106T075938, end_date=20241106T075938
[2024-11-06T07:59:38.975+0000] {standard_task_runner.py:107} ERROR - Failed to execute job 58 for task check_file (The conn_id `my_filesystem_connection` isn't defined; 4817)
[2024-11-06T07:59:39.012+0000] {local_task_job_runner.py:234} INFO - Task exited with return code 1
[2024-11-06T07:59:39.071+0000] {taskinstance.py:3280} INFO - 0 downstream tasks scheduled from follow-on schedule check
