[2024-11-07T07:28:08.157+0000] {taskinstance.py:1956} INFO - Dependencies all met for dep_context=non-requeueable deps ti=<TaskInstance: openweatherdata_dag.task_1 manual__2024-11-07T07:28:02.796975+00:00 [queued]>
[2024-11-07T07:28:08.174+0000] {taskinstance.py:1956} INFO - Dependencies all met for dep_context=requeueable deps ti=<TaskInstance: openweatherdata_dag.task_1 manual__2024-11-07T07:28:02.796975+00:00 [queued]>
[2024-11-07T07:28:08.175+0000] {taskinstance.py:2170} INFO - Starting attempt 1 of 1
[2024-11-07T07:28:08.206+0000] {taskinstance.py:2191} INFO - Executing <Task(PythonOperator): task_1> on 2024-11-07 07:28:02.796975+00:00
[2024-11-07T07:28:08.253+0000] {standard_task_runner.py:60} INFO - Started process 5663 to run task
[2024-11-07T07:28:08.259+0000] {standard_task_runner.py:87} INFO - Running: ['***', 'tasks', 'run', 'openweatherdata_dag', 'task_1', 'manual__2024-11-07T07:28:02.796975+00:00', '--job-id', '74', '--raw', '--subdir', 'DAGS_FOLDER/model_meteo.py', '--cfg-path', '/tmp/tmphdh3xbg8']
[2024-11-07T07:28:08.261+0000] {standard_task_runner.py:88} INFO - Job 74: Subtask task_1
[2024-11-07T07:28:08.289+0000] {warnings.py:109} WARNING - /home/***/.local/lib/python3.8/site-packages/***/settings.py:194: DeprecationWarning: The sql_alchemy_conn option in [core] has been moved to the sql_alchemy_conn option in [database] - the old setting has been used, but please update your config.
  SQL_ALCHEMY_CONN = conf.get("database", "SQL_ALCHEMY_CONN")

[2024-11-07T07:28:08.379+0000] {task_command.py:423} INFO - Running <TaskInstance: openweatherdata_dag.task_1 manual__2024-11-07T07:28:02.796975+00:00 [running]> on host 8a2ba9ce15fe
[2024-11-07T07:28:08.601+0000] {taskinstance.py:2480} INFO - Exporting env vars: AIRFLOW_CTX_DAG_OWNER='***' AIRFLOW_CTX_DAG_ID='openweatherdata_dag' AIRFLOW_CTX_TASK_ID='task_1' AIRFLOW_CTX_EXECUTION_DATE='2024-11-07T07:28:02.796975+00:00' AIRFLOW_CTX_TRY_NUMBER='1' AIRFLOW_CTX_DAG_RUN_ID='manual__2024-11-07T07:28:02.796975+00:00'
[2024-11-07T07:28:08.604+0000] {taskinstance.py:2698} ERROR - Task failed with exception
Traceback (most recent call last):
  File "/home/airflow/.local/lib/python3.8/site-packages/airflow/models/taskinstance.py", line 433, in _execute_task
    result = execute_callable(context=context, **execute_callable_kwargs)
  File "/home/airflow/.local/lib/python3.8/site-packages/airflow/operators/python.py", line 199, in execute
    return_value = self.execute_callable()
  File "/home/airflow/.local/lib/python3.8/site-packages/airflow/operators/python.py", line 216, in execute_callable
    return self.python_callable(*self.op_args, **self.op_kwargs)
  File "/opt/airflow/dags/model_meteo.py", line 28, in get_data
    with open(f"data/raw_files/{filename}.json", "w") as outfile:
FileNotFoundError: [Errno 2] No such file or directory: 'data/raw_files/2024-11-07 07:11.json'
[2024-11-07T07:28:08.626+0000] {taskinstance.py:1138} INFO - Marking task as FAILED. dag_id=openweatherdata_dag, task_id=task_1, execution_date=20241107T072802, start_date=20241107T072808, end_date=20241107T072808
[2024-11-07T07:28:08.651+0000] {standard_task_runner.py:107} ERROR - Failed to execute job 74 for task task_1 ([Errno 2] No such file or directory: 'data/raw_files/2024-11-07 07:11.json'; 5663)
[2024-11-07T07:28:08.713+0000] {local_task_job_runner.py:234} INFO - Task exited with return code 1
[2024-11-07T07:28:08.765+0000] {taskinstance.py:3280} INFO - 0 downstream tasks scheduled from follow-on schedule check
